<?xml version="1.0"?>
<robot xmlns:xacro="http://www.ros.org/wiki/xacro" name="bionic_hand">

<!-- Color Definition -->
	<material name="color_white">	<color rgba="1 1 1 1"/></material>
	<material name="color_yellow"><color rgba="1 1 0 1"/></material>

<!-- Dirn/Locn Macro -->
	<xacro:macro name="axis_000" params="">	<axis xyz="0 0 0"/></xacro:macro>
	<xacro:macro name="axis_y" params="">	 	<axis xyz="0 1 0"/></xacro:macro>
	<xacro:macro name="rpy_000" params="">	<origin rpy="0 0 0"/></xacro:macro>
	
<!-- Shape macros -->
	<xacro:macro name="shape_box_lower_segment" params=""> 
  	<geometry><box size="0.06 0.03 0.02"/></geometry>
	</xacro:macro>

  <!-- Redefine Shape top here -->
  <xacro:macro name="shape_box_upper_segment" params=""> 
  	<geometry><box size="0.06 0.03 0.02"/></geometry>
	</xacro:macro>

  <!-- Create Shape thumb lower here -->
  <xacro:macro name="shape_box_thumb_lower_segment" params=""> 
  	<geometry><box size="0.08 0.03 0.02"/></geometry>
	</xacro:macro>

<!-- Link Macros -->
  <xacro:macro name="lower_link" params="name color_macro"> 
    <link name="${name}">
      <visual>
        <origin xyz="0.025 0 0" rpy="0 0 0"/>
        <xacro:shape_box_lower_segment/> 
        <material name="${color_macro}"/>
      </visual>
    </link>
  </xacro:macro>

  <xacro:macro name="upper_link" params="name color_macro"> 
    <link name="${name}">
      <visual>
        <origin xyz="0.025 0 0" rpy="0 0 0"/>
        <xacro:shape_box_upper_segment/> 
        <material name="${color_macro}"/>
      </visual>
    </link>
  </xacro:macro>

  <xacro:macro name="thumb_link" params="name color_macro"> 
    <link name="${name}">
      <visual>
        <origin xyz="0.025 0 0" rpy="0 0 0"/>
        <xacro:shape_box_thumb_lower_segment/> 
        <material name="${color_macro}"/>
      </visual>
    </link>
  </xacro:macro>

<!-- Macro for a finger joint -->
  <xacro:macro name="joint_limits" params="">
    <limit lower="0" upper="1.57" effort="10" velocity="1"/>
  </xacro:macro>

  <xacro:macro name="finger_joint" params="name parent child xyz rpy axis">
    <joint name="${name}" type="revolute">
      <parent link="${parent}"/>
      <child link="${child}"/>
      <origin xyz="${xyz}" rpy="${rpy}"/>
      <axis xyz="${axis}"/>
      <xacro:joint_limits/>
    </joint>
  </xacro:macro>

<!-- Base link -->
  <link name="base_link">
    <visual>
      <geometry>
        <box size="0.18 0.125 0.02"/> 
      </geometry>
      <material>
        <color rgba="1 0.5 0 1"/>
      </material>
    </visual>
  </link>

<!-- Define fingers using macros -->
  <!-- Index -->
	  <xacro:lower_link name="index_lower" color_macro="color_white"/>
	  <xacro:upper_link name="index_upper" color_macro="color_yellow"/>
    <xacro:finger_joint 
    name="index_lower_joint" 
    parent="base_link" 
    child="index_lower" 
    xyz="0.095 0.048 0" rpy="0 0 0" axis="0 1 0"/>
    <xacro:finger_joint 
      name="index_upper_joint" 
      parent="index_lower" 
      child="index_upper" 
      xyz="0.06 0 0" rpy="0 0 0" axis="0 1 0"/>

  <!-- Middle -->
    <xacro:lower_link name="middle_lower" color_macro="color_white"/>
	  <xacro:upper_link name="middle_upper" color_macro="color_yellow"/>
    <xacro:finger_joint 
    name="middle_lower_joint" 
    parent="base_link" 
    child="middle_lower" 
    xyz="0.095 0.016 0" rpy="0 0 0" axis="0 1 0"/>
    <xacro:finger_joint 
      name="middle_upper_joint" 
      parent="middle_lower" 
      child="middle_upper" 
      xyz="0.06 0 0" rpy="0 0 0" axis="0 1 0"/>

  <!-- Ring  -->
    <xacro:lower_link name="ring_lower" color_macro="color_white"/>
	  <xacro:upper_link name="ring_upper" color_macro="color_yellow"/>
    <xacro:finger_joint 
    name="ring_lower_joint" 
    parent="base_link" 
    child="ring_lower" 
    xyz="0.095 -0.016 0" rpy="0 0 0" axis="0 1 0"/>
    <xacro:finger_joint 
      name="ring_upper_joint" 
      parent="ring_lower" 
      child="ring_upper" 
      xyz="0.06 0 0" rpy="0 0 0" axis="0 1 0"/>

  <!-- Pinky -->
    <xacro:lower_link name="pinky_lower" color_macro="color_white"/>
	  <xacro:upper_link name="pinky_upper" color_macro="color_yellow"/>
    <xacro:finger_joint 
      name="pinky_lower_joint" 
      parent="base_link" 
      child="pinky_lower" 
      xyz="0.095 -0.048 0" rpy="0 0 0" axis="0 1 0"/>
    <xacro:finger_joint 
      name="pinky_upper_joint" 
      parent="pinky_lower" 
      child="pinky_upper" 
      xyz="0.06 0 0" rpy="0 0 0" axis="0 1 0"/>

  <!-- Thumb -->
    <xacro:lower_link name="thumb_lower" color_macro="color_white"/>
	  <xacro:upper_link name="thumb_upper" color_macro="color_yellow"/>
    <xacro:finger_joint 
      name="thumb_lower_joint" 
      parent="base_link" 
      child="thumb_lower" 
      xyz="-0.02 0.055 0" 
      rpy="-0.78 0 1.57" 
      axis="0 1 0"/>
    <xacro:finger_joint 
      name="thumb_upper_joint" 
      parent="thumb_lower" 
      child="thumb_upper" 
      xyz="0.06 0 0" rpy="0 0 0" axis="0 1 0"/>

</robot>
